<sdf version='1.5'>
  <model name='hummingbird_fixed'>
    <link name='base_link'>
      <pose>0 0 0.2 0 -0 0</pose>
      <frame name='base_link'>
        <pose>0 0 0.0 0 -0 0</pose>
      </frame>
      <inertial>
        <pose>0 0 0.157 0 -0 0</pose>
        <mass>0.5</mass>
        <inertia>
          <ixx>0.0147563</ixx>
          <ixy>0</ixy>
          <ixz>0</ixz>
          <iyy>0.00638929</iyy>
          <iyz>0</iyz>
          <izz>0.0177</izz>
        </inertia>
      </inertial>
      <collision name='base_link_collision'>
        <pose>0 0 0 0 -0 0</pose>
        <geometry>
          <box>
            <size>0.2 0.6 0.06</size>
          </box>
        </geometry>
        <surface>
          <contact>
            <ode>
              <max_vel>10</max_vel>
              <min_depth>0.01</min_depth>
            </ode>
          </contact>
          <friction>
            <ode/>
          </friction>
        </surface>
      </collision>
      <visual name='base_link_visual'>
        <pose>0 0 0.27 0 -1.57075 0</pose>
        <geometry>
          <mesh>
            <scale>0.0006 0.0007 0.0007</scale>
            <uri>model://hummingbird/meshes/pacflyer_s100_mockup.dae</uri>
          </mesh>
        </geometry>
        <material>
          <script>
            <name>Gazebo/DarkGrey</name>
            <uri>__default__</uri>
          </script>
        </material>
      </visual>
      <gravity>1</gravity>
      <velocity_decay/>
      <self_collide>0</self_collide>
    </link>
    <link name='rotor_left'>
      <pose>0.0 -0.195 0.4685 0 -0 0</pose>
      <inertial>
        <pose>0 0 0 0 -0 0</pose>
        <mass>0.005</mass>
        <inertia>
          <ixx>9.75e-07</ixx>
          <ixy>0</ixy>
          <ixz>0</ixz>
          <iyy>0.000166704</iyy>
          <iyz>0</iyz>
          <izz>0.000167604</izz>
        </inertia>
      </inertial>
      <collision name='rotor_left_collision'>
        <pose>0 0 0 0 -0 0</pose>
        <geometry>
          <cylinder>
            <length>0.005</length>
            <radius>0.1</radius>
          </cylinder>
        </geometry>
        <surface>
          <contact>
            <ode/>
          </contact>
          <friction>
            <ode/>
          </friction>
        </surface>
      </collision>
      <visual name='rotor_left_visual'>
        <pose>0 0 0 0 -0 0</pose>
        <geometry>
          <mesh>
            <scale>1 1 1</scale>
            <uri>model://hummingbird/meshes/iris_prop_cw.dae</uri>
          </mesh>
        </geometry>
        <material>
          <script>
            <name>Gazebo/Blue</name>
            <uri>__default__</uri>
          </script>
        </material>
      </visual>
      <gravity>1</gravity>
      <velocity_decay/>
      <self_collide>0</self_collide>
    </link>
    <link name='rotor_right'>
      <pose>0.0 0.195 0.4685 0 -0 0</pose>
      <inertial>
        <pose>0 0 0 0 -0 0</pose>
        <mass>0.005</mass>
        <inertia>
          <ixx>9.75e-07</ixx>
          <ixy>0</ixy>
          <ixz>0</ixz>
          <iyy>0.000166704</iyy>
          <iyz>0</iyz>
          <izz>0.000167604</izz>
        </inertia>
      </inertial>
      <collision name='rotor_right_collision'>
        <pose>0 0 0 0 -0 0</pose>
        <geometry>
          <cylinder>
            <length>0.005</length>
            <radius>0.1</radius>
          </cylinder>
        </geometry>
        <surface>
          <contact>
            <ode/>
          </contact>
          <friction>
            <ode/>
          </friction>
        </surface>
      </collision>
      <visual name='rotor_right_visual'>
        <pose>0 0 0 0 -0 0</pose>
        <geometry>
          <mesh>
            <scale>1 1 1</scale>
            <uri>model://hummingbird/meshes/iris_prop_ccw.dae</uri>
          </mesh>
        </geometry>
        <material>
          <script>
            <name>Gazebo/DarkGrey</name>
            <uri>__default__</uri>
          </script>
        </material>
      </visual>
      <gravity>1</gravity>
      <velocity_decay/>
      <self_collide>0</self_collide>
    </link>
    <link name="left_elevon">
      <pose>0 0.195 0.2365 0 0 0</pose>
      <inertial>
        <mass>0.00000001</mass>
        <inertia>
          <ixx>0.000001</ixx>
          <ixy>0.0</ixy>
          <iyy>0.000001</iyy>
          <ixz>0.0</ixz>
          <iyz>0.0</iyz>
          <izz>0.000001</izz>
        </inertia>
      </inertial>
      <visual name="left_elevon_visual">
        <pose>0 0.0 0.0 0 0 0</pose>
        <geometry>
          <box>
            <size> 0.015 0.22 0.07347</size>
          </box>
        </geometry>
      </visual>
    </link>
    <link name="right_elevon">
      <pose>0 -0.195 0.2365 0 0 0</pose>
      <inertial>
        <mass>0.00000001</mass>
        <inertia>
          <ixx>0.000001</ixx>
          <ixy>0.0</ixy>
          <iyy>0.000001</iyy>
          <ixz>0.0</ixz>
          <iyz>0.0</iyz>
          <izz>0.000001</izz>
        </inertia>
      </inertial>
      <visual name="left_elevon_visual">
        <pose>0 -0.0 0.0 0 0 0</pose>
        <geometry>
          <box>
            <size> 0.015  0.22 0.07347</size>
          </box>
        </geometry>
      </visual>
    </link>

    <link name="tag0">
      <inertial>
        <mass>0.00000001</mass>
        <inertia>
          <ixx>1e-9</ixx>
          <ixy>0</ixy>
          <ixz>0</ixz>
          <iyy>1e-9</iyy>
          <iyz>0</iyz>
          <izz>1e-9</izz>
        </inertia>
        <pose frame=''>0 0 0 0 -0 0</pose>
      </inertial>
      <pose frame=''>0.02 -0.14 0.357  0 0 1.57079</pose>
      <collision name="collision">
        <geometry>
          <box>
            <size>.10 0.001 .10</size>
          </box>
        </geometry>
      </collision>
      <visual name="visual">
        <cast_shadows>false</cast_shadows>
        <geometry>
          <box>
            <size>.10 0.001 .10</size>
          </box>
        </geometry>
        <material>
          <script>
            <uri>model://Tag0/materials/scripts</uri>
            <uri>model://Tag0/materials/textures</uri>
            <name>vrc/Tag0</name>
          </script>
        </material>
      </visual>
    </link>
    <link name="tag1">
      <inertial>
        <mass>0.00000001</mass>
        <inertia>
          <ixx>1e-9</ixx>
          <ixy>0</ixy>
          <ixz>0</ixz>
          <iyy>1e-9</iyy>
          <iyz>0</iyz>
          <izz>1e-9</izz>
        </inertia>
        <pose frame=''>0 0 0 0 -0 0</pose>
      </inertial>
      <pose frame=''>0.02 0.14 0.357  0 0 1.57079</pose>
      <collision name="collision">
        <geometry>
          <box>
            <size>.10 0.001 .10</size>
          </box>
        </geometry>
      </collision>
      <visual name="visual">
        <cast_shadows>false</cast_shadows>
        <geometry>
          <box>
            <size>.10 0.001 .10</size>
          </box>
        </geometry>
        <material>
          <script>
            <uri>model://Tag1/materials/scripts</uri>
            <uri>model://Tag1/materials/textures</uri>
            <name>vrc/Tag1</name>
          </script>
        </material>
      </visual>
    </link>
    <link name="tag2">
      <inertial>
        <mass>0.00000001</mass>
        <inertia>
          <ixx>1e-9</ixx>
          <ixy>0</ixy>
          <ixz>0</ixz>
          <iyy>1e-9</iyy>
          <iyz>0</iyz>
          <izz>1e-9</izz>
        </inertia>
        <pose frame=''>0 0 0 0 -0 0</pose>
      </inertial>
      <pose frame=''>-0.02 -0.14 0.357  0 0 1.57079</pose>
      <collision name="collision">
        <geometry>
          <box>
            <size>.10 0.001 .10</size>
          </box>
        </geometry>
      </collision>
      <visual name="visual">
        <cast_shadows>false</cast_shadows>
        <geometry>
          <box>
            <size>.1 0.001 .1</size>
          </box>
        </geometry>
        <material>
          <script>
            <uri>model://Tag2/materials/scripts</uri>
            <uri>model://Tag2/materials/textures</uri>
            <name>vrc/Tag2</name>
          </script>
        </material>
      </visual>
    </link>
    <link name="tag3">
      <inertial>
        <mass>0.00000001</mass>
        <inertia>
          <ixx>1e-9</ixx>
          <ixy>0</ixy>
          <ixz>0</ixz>
          <iyy>1e-9</iyy>
          <iyz>0</iyz>
          <izz>1e-9</izz>
        </inertia>
        <pose frame=''>0 0 0 0 -0 0</pose>
      </inertial>
      <pose frame=''>-0.02 0.14 0.357  0 0 1.57079</pose>
      <collision name="collision">
        <geometry>
          <box>
            <size>.10 0.001 .10</size>
          </box>
        </geometry>
      </collision>
      <visual name="visual">
        <cast_shadows>false</cast_shadows>
        <geometry>
          <box>
            <size>.1 0.001 .1</size>
          </box>
        </geometry>
        <material>
          <script>
            <uri>model://Tag3/materials/scripts</uri>
            <uri>model://Tag3/materials/textures</uri>
            <name>vrc/Tag3</name>
          </script>
        </material>
      </visual>
    </link>
    <link name="tag4">
      <inertial>
        <mass>0.00000001</mass>
        <inertia>
          <ixx>1e-9</ixx>
          <ixy>0</ixy>
          <ixz>0</ixz>
          <iyy>1e-9</iyy>
          <iyz>0</iyz>
          <izz>1e-9</izz>
        </inertia>
        <pose frame=''>0 0 0 0 -0 0</pose>
      </inertial>
      <pose frame=''>-0.02 -0.054 0.382  0 0 1.57079</pose>
      <collision name="collision">
        <geometry>
          <box>
            <size>.05 0.001 .05</size>
          </box>
        </geometry>
      </collision>
      <visual name="visual">
        <cast_shadows>false</cast_shadows>
        <geometry>
          <box>
            <size>.05 0.001 .05</size>
          </box>
        </geometry>
        <material>
          <script>
            <uri>model://Tag4/materials/scripts</uri>
            <uri>model://Tag4/materials/textures</uri>
            <name>vrc/Tag4</name>
          </script>
        </material>
      </visual>
    </link>
    <link name="tag5">
      <inertial>
        <mass>0.00000001</mass>
        <inertia>
          <ixx>1e-9</ixx>
          <ixy>0</ixy>
          <ixz>0</ixz>
          <iyy>1e-9</iyy>
          <iyz>0</iyz>
          <izz>1e-9</izz>
        </inertia>
        <pose frame=''>0 0 0 0 -0 0</pose>
      </inertial>
      <pose frame=''>-0.02 0.054 0.382  0 0 1.57079</pose>
      <collision name="collision">
        <geometry>
          <box>
            <size>.05 0.001 .05</size>
          </box>
        </geometry>
      </collision>
      <visual name="visual">
        <cast_shadows>false</cast_shadows>
        <geometry>
          <box>
            <size>.05 0.001 .05</size>
          </box>
        </geometry>
        <material>
          <script>
            <uri>model://Tag5/materials/scripts</uri>
            <uri>model://Tag5/materials/textures</uri>
            <name>vrc/Tag5</name>
          </script>
        </material>
      </visual>
    </link>

    <link name='hummingbird/imu_link'>
      <pose>0 0 0.357 0 -0 0</pose>
      <inertial>
        <pose>0 0 0 0 -0 0</pose>
        <mass>0.015</mass>
        <inertia>
          <ixx>1e-05</ixx>
          <ixy>0</ixy>
          <ixz>0</ixz>
          <iyy>1e-05</iyy>
          <iyz>0</iyz>
          <izz>1e-05</izz>
        </inertia>
      </inertial>
    </link>

    <joint name='hummingbird/imu_joint' type='fixed'>
      <child>hummingbird/imu_link</child>
      <parent>base_link</parent>
    </joint>
    <joint name='rotor_left_joint' type='revolute'>
      <child>rotor_left</child>
      <parent>base_link</parent>
      <axis>
        <xyz>0 0 1</xyz>
        <limit>
          <lower>-1e+16</lower>
          <upper>1e+16</upper>
        </limit>
        <dynamics>
          <spring_reference>0</spring_reference>
          <spring_stiffness>0</spring_stiffness>
        </dynamics>
        <use_parent_model_frame>1</use_parent_model_frame>
      </axis>
    </joint>
    <joint name='rotor_right_joint' type='revolute'>
      <child>rotor_right</child>
      <parent>base_link</parent>
      <axis>
        <xyz>0 0 1</xyz>
        <limit>
          <lower>-1e+16</lower>
          <upper>1e+16</upper>
        </limit>
        <dynamics>
          <spring_reference>0</spring_reference>
          <spring_stiffness>0</spring_stiffness>
        </dynamics>
        <use_parent_model_frame>1</use_parent_model_frame>
      </axis>
    </joint>

    <joint name='hummingbird_back_left_tag' type='fixed'>
      <parent>base_link</parent>
      <child>tag0</child>
      <pose frame=''>0 0 0 0 -0 0</pose>
    </joint>
    <joint name='hummingbird_back_right_tag' type='fixed'>
      <parent>base_link</parent>
      <child>tag1</child>
      <pose frame=''>0 0 0 0 -0 0</pose>
    </joint>
    <joint name='hummingbird_front_left_tag' type='fixed'>
      <parent>base_link</parent>
      <child>tag2</child>
      <pose frame=''>0 0 0 0 -0 0</pose>
    </joint>
    <joint name='hummingbird_front_right_tag' type='fixed'>
      <parent>base_link</parent>
      <child>tag3</child>
      <pose frame=''>0 0 0 0 -0 0</pose>
    </joint>
    <joint name='hummingbird_front_left_tag_small' type='fixed'>
      <parent>base_link</parent>
      <child>tag4</child>
      <pose frame=''>0 0 0 0 -0 0</pose>
    </joint>
    <joint name='hummingbird_front_right_tag_small' type='fixed'>
      <parent>base_link</parent>
      <child>tag5</child>
      <pose frame=''>0 0 0 0 -0 0</pose>
    </joint>
    <joint name='hummingbird_realsense' type='fixed'>
      <parent>base_link</parent>
      <child>realsense_camera::link</child>
      <pose frame=''>0 0 0 0 -0 0</pose>
      <physics>
        <ode>
          <limit>
            <cfm>0</cfm>
            <erp>0.2</erp>
          </limit>
          <suspension>
            <cfm>0</cfm>
            <erp>0.2</erp>
          </suspension>
        </ode>
      </physics>
    </joint>
    <joint name='left_elevon_joint' type='revolute'>
      <parent>base_link</parent>
      <child>left_elevon</child>
      <pose>0 0.0 0.03 0.00 0 0.0</pose>
      <axis>
        <xyz>0 1 0</xyz>
        <limit>
          <!-- -30/+30 deg. -->
          <lower>-1.05</lower>
          <upper>1.05</upper>
        </limit>
        <dynamics>
          <damping>1.000</damping>
        </dynamics>
      </axis>
      <physics>
        <ode>
          <implicit_spring_damper>1</implicit_spring_damper>
        </ode>
      </physics>
    </joint>
    <joint name='right_elevon_joint' type='revolute'>
      <parent>base_link</parent>
      <child>right_elevon</child>
      <pose>0 0.0 0.03 0.00 0 0.0</pose>
      <axis>
        <xyz>0 1 0</xyz>
        <limit>
          <!-- -30/+30 deg. -->
          <lower>-0.53</lower>
          <upper>0.53</upper>
        </limit>
        <dynamics>
          <damping>1.000</damping>
        </dynamics>
      </axis>
      <physics>
        <ode>
          <implicit_spring_damper>1</implicit_spring_damper>
        </ode>
      </physics>
    </joint>

    <static>false</static>
  </model>
</sdf>
